Workbook

Sheet 0_README
A1: DAY 28 — MONETIZATION MODEL
A2: AI Pricing · GTM · Evidence — AI-IN-ACTION Track 1
A4: QUY ƯỚC MÀU — CHỈ ĐIỀN VÀO Ô MÀU VÀNG
A5: Ô VÀNG, chữ xanh dương | B5: Ô bạn phải điền
A6: Ô XÁM, chữ đen | B6: Công thức tự tính — KHÔNG SỬA
A7: Chữ xanh lá | B7: Link sang tab khác
A8: Ô XÁM đậm nhạt | B8: Bảng tham chiếu, chỉ đọc
A10: THỨ TỰ LÀM — 6 TRẠM, 120 PHÚT
A11: Trạm 1 · 15' | B11: Ngân sách khách & định nghĩa Job → điền S1–S2 của tab 1_Cost_Job
A12: Trạm 2 · 20' | B12: Value Metric → tab 3_Value_Metric
A13: Trạm 3 · 30' | B13: Cost/Job, giá sàn & giá trần → tab 1_Cost_Job (S3–S8) rồi 2_Pricing
A14: Trạm 4 · 20' | B14: Kênh phân phối & Affordability Test → tab 4_Channel_Fit
A15: Trạm 5 · 15' | B15: Pain Moment & 90-Day Plan → tab 5_90Day_Plan
A16: Trạm 6 · 20' | B16: Evidence Pack & ráp One-Pager → tab 5_90Day_Plan + file .docx
A18: 3 QUY TẮC KHÔNG ĐƯỢC PHÁ
A19: 1. Chia cho số job HOÀN THÀNH, không phải số job đã thử.
A20: 2. HITL và Retry không được để 0 nếu không có lý do viết ra được.
A21: 3. Mọi con số giá API phải có NGÀY kiểm tra (xem tab 6_Benchmarks).
A23: Giá tham chiếu trong workbook này được chốt ngày 26/08/2026. Nhiều mức giá là KHUYẾN MẠI CÓ HẠN.
A24: Bạn PHẢI tự mở lại trang giá của nhà cung cấp và cập nhật — đây là một phần của bài tập.

Sheet 1_Cost_Job
A1: TAB 1 — COST/JOB CALCULATOR
A2: Trạm 1 (S1–S2) và Trạm 3 (S3–S8). Chỉ điền ô vàng.
A4: S1. ĐỊNH NGHĨA JOB
A5: 1 job của bạn là gì? | B5: 1 ván Ma Sói do AI quản trò điều hành trọn vẹn đến lúc công bố phe thắng, không cần người can thiệp. KHÔNG tính ván bị hủy giữa chừng (lỗi bot hoặc người chơi bỏ). | D5: Phải là thứ KHÁCH coi là giá trị — không phải '1 request' | E5: Đếm tự động: ván có trạng thái kết thúc GAME_OVER trong engine FSM + eventLogger (đang làm, 08/10/2026).
A6: Biến thể HITL: A hay B? | B6: A | D6: A = khách tự xử lý ca escalate · B = BẠN chịu (outcome/managed) | E6: Biến thể A: bán phần mềm. Ván lỗi thì người chơi tự mở ván mới, không có người của mình xử lý thay. Chỉ tính QA nội bộ.
A8: S2. KHỐI LƯỢNG
A9: Số job THỬ / tháng | B9: 3000 | C9: job | E9: GIẢ ĐỊNH quy mô mục tiêu tháng 4+: 100 server × 30 ván/tháng. Ở quy mô pilot nhỏ hơn GM thấp hơn — xem bảng 'Theo khối lượng' ở tab 2.
A10: Containment rate (AI tự làm xong) | B10: 0.857 | D10: Chưa đo → ước tính và ghi rõ | E10: CHƯA ĐO tỷ lệ ván hoàn thành. Tạm dùng 85,7% = độ chính xác nội dung AI ở eval Gate 2 (12/14 bước, 04/10/2026). Brief đặt mục tiêu ≥ 75%. Đo thật bằng eventLogger trước 08/11/2026.
A11: → Số job HOÀN THÀNH / tháng | B11: =B9*B10 -> 2571 | C11: job | D11: MẪU SỐ của Cost/Job
A12: → Số job KHÔNG xong / tháng | B12: =B9-B11 -> 429 | C12: job | D12: Số ca phải escalate
A14: S3. API — LLM | F14: BẢNG PHỤ — TOKEN / VÁN (đo bằng tiktoken o200k_base, 08/10/2026)
A15: Giá input ($ / 1M token) | B15: 0.15 | D15: Claude Haiku 4.5 — xem tab 6_Benchmarks | E15: gpt-4o-mini (model đang chạy, src/config.py). Giá kiểm tra 08/10/2026 tại developers.openai.com/api/docs/pricing | F15: Lời gọi LLM | G15: Số lần / ván | H15: Token input / lần | I15: Token output / lần
A16: Giá output ($ / 1M token) | B16: 0.6 | F16: Mở màn (intro) | G16: 1 | H16: 315 | I16: =150*$G$27 -> 228
A17: Giá cache WRITE ($ / 1M token) | B17: 0.15 | D17: Anthropic 5-phút = 1,25× input | E17: OpenAI không thu phí ghi cache: lần đầu tính như input thường. | F17: Chạng vạng (dusk) | G17: =$G$25 -> 2 | H17: 243 | I17: =80*$G$27 -> 121.6
A18: Giá cache READ ($ / 1M token) | B18: 0.075 | D18: ≈ 0,1× input (giảm 90%) | E18: OpenAI cached input = $0,075 (50% input, không phải 10%). | F18: Bình minh (dawn) | G18: =$G$25 -> 2 | H18: 241 | I18: =80*$G$27 -> 121.6
A19: Số lượt (turns) / job | B19: =G23 -> 13 | C19: lượt | E19: Số lời gọi LLM / ván, lấy từ bảng phụ F15:I23. | F19: Tóm tắt buổi sáng | G19: =$G$25 -> 2 | H19: 421 | I19: =120*$G$27 -> 182.4
A20: Token input CACHE ĐƯỢC / lượt | B20: 0 | C20: token | D20: System prompt + KB + few-shot | E20: Để 0 (thận trọng): prompt dẫn chuyện < 1.024 token nên OpenAI không cache. Chỉ prompt hỏi luật cache được — mức tiết kiệm ở G32:G33. | F20: Treo cổ (lynch) | G20: =$G$25 -> 2 | H20: 494 | I20: =120*$G$27 -> 182.4
A21: Token input FRESH / lượt | B21: =H23/G23 -> 2239.3846 | C21: token | D21: Câu hỏi khách + dữ liệu động | E21: Token input trung bình / lời gọi = tổng input / số lời gọi (bảng phụ). | F21: Tổng kết thắng thua | G21: 1 | H21: 445 | I21: =120*$G$27 -> 182.4
A22: Token output / lượt | B22: =I23/G23 -> 153.16923 | C22: token | F22: Hỏi luật (gửi cả rulebook) | G22: =$G$26 -> 3 | H22: 8518 | I22: =80*$G$27 -> 121.6
A23: → Cache write / job | B23: =B20*B17/1000000 -> 0 | F23: → TỔNG / ván | G23: =SUM(G16:G22) -> 13 | H23: =SUMPRODUCT(G16:G22,H16:H22) -> 29112 | I23: =SUMPRODUCT(G16:G22,I16:I22) -> 1991.2
A24: → Cache read / job | B24: =(B19-1)*B20*B18/1000000 -> 0
A25: → Input fresh / job | B25: =B19*B21*B15/1000000 -> 0.0043668 | F25: Số vòng ngày–đêm / ván (ước tính) | G25: 2
A26: → Output / job | B26: =B19*B22*B16/1000000 -> 0.00119472 | F26: Số câu hỏi luật / ván (ước tính) | G26: 3
A27: → LLM / job — CÓ prompt caching | B27: =SUM(B23:B26) -> 0.00556152 | F27: Token / từ tiếng Việt (đo) | G27: 1.52
A28: → LLM / job — KHÔNG cache | B28: =B19*(B20+B21)*B15/1000000+B26 -> 0.00556152 | F28: Input = prompt thật trong src/agents/narrator/prompts.py và RULEBOOK_PROMPT_TEMPLATE (đã điền persona Gothic). Output = giới hạn số từ trong code × 1,52 token/từ (đo trên 81 câu mẫu fallback_templates.json). 2 vòng: ván 5 người 1 Sói, Sói thắng sớm nhất ở sáng vòng 2, Dân có thể thắng ngay vòng 1.
A29: → % tiết kiệm nhờ caching | B29: =IF(B28=0,0,1-B27/B28) -> 0 | D29: Đòn bẩy rẻ nhất bạn có
A30: Dùng Batch API? (1 = có, 0 = không) | B30: 0 | D30: Batch giảm 50% — chỉ khi job KHÔNG cần realtime | E30: Không dùng Batch: lời dẫn phải hiện ngay trong ván (realtime).
A31: → LLM / job sau Batch | B31: =B27*(1-B30*0.5) -> 0.00556152 | F31: Nếu bật cache prompt hỏi luật (chưa tính vào mô hình chính)
F32: → LLM / ván khi câu hỏi luật thứ 2, 3 đọc cache | G32: =B27-(G26-1)*8201*(B15-B18)/1000000 -> 0.00433137
A33: S4. API — SPEECH (để 0 nếu sản phẩm không có thoại) | F33: → % tiết kiệm | G33: =IF(B27=0,0,1-G32/B27) -> 0.22118953
A34: Giá STT ($ / phút) | B34: 0 | D34: Deepgram streaming list $0,0077/phút | E34: Bản đang chạy chỉ có text. TTS mới là tính năng dự kiến (brief), chưa triển khai → 0.
A35: Số phút audio / job | B35: 0 | C35: phút | F35: INFRA — bảng phụ
A36: Giá TTS ($ / 1M ký tự) | B36: 0 | D36: ElevenLabs Flash $50 · Google Standard $4 | F36: Railway Pro ($ / tháng, đã gồm $20 usage) | G36: 20
A37: Số ký tự TTS / job | B37: 0 | C37: ký tự | D37: ≈ 900 ký tự cho mỗi phút bot nói | F37: Phí Discord Premium Apps (% doanh thu) | G37: 0.15
A38: → Speech / job | B38: =B34*B35+B36*B37/1000000 -> 0 | F38: → Railway / ván thử | G38: =IF(B9=0,0,G36/B9) -> 0.0066666667
F39: → Phí Discord / ván (theo giá ở tab 2) | G39: ='2_Pricing'!B19*G37 -> 0.01995
A40: S5. INFRA | F40: → Infra / ván | G40: =G38+G39 -> 0.026616667
A41: Infra / job ($) | B41: =G40 -> 0.026616667 | D41: Vector DB, embedding, storage, logging | E41: Railway chia theo ván + phí Discord 15% trên mỗi ván bán ra (bảng phụ F35:G40). | F41: Railway: railway.com/pricing (08/10/2026). GIẢ ĐỊNH app + Redis + Postgres dùng ≤ $20 usage (≈1 GB RAM $10 + 0,5 vCPU $10) — cần đối chiếu hóa đơn thật. Discord: 15% cho $1M doanh thu đầu, từ 06/06/2024 (discord.com/blog/feast-your-moniteyes-on-todays-exciting-developer-updates). Vector DB: không có — rulebook nằm trong prompt.
A42: Telephony ($ / phút) | B42: 0 | E42: Không có điện thoại.
A43: → Infra / job | B43: =B41+B42*B35 -> 0.026616667
...

Sheet 2_Pricing
A1: TAB 2 — PRICING SANITY CHECK
A2: Trạm 3. Cost/Job tự lấy từ tab 1. Bạn điền giá bán và các con số neo giá.
A4: GIÁ SÀN
A5: Cost/Job (từ tab 1_Cost_Job) | B5: ='1_Cost_Job'!B66 -> 0.043445419 | C5: $/job
A6: Hệ số an toàn tối thiểu | B6: 3 | C6: × | D6: Giá bán ≥ 3 × Cost/Job
A7: → GIÁ SÀN | B7: =B5*B6 -> 0.13033626 | C7: $/job
A9: GIÁ TRẦN — NEO THEO THỨ KHÁCH ĐANG CHI | F9: NEO GIÁ — bảng phụ
A10: Giá trị khách tiết kiệm được / tháng ($) | B10: =G12*B11 -> 5.846389 | D10: Neo theo giá trị | E10: Giá trị khách nhận = thời gian 1 người được giải phóng khỏi vai quản trò để vào chơi. Chưa có dữ liệu giá trị nào khác → dùng chung số với neo nhân công. | F10: Thời gian quản trò / ván (giờ, ước tính) | G10: 0.2
A11: Số job / tháng của 1 khách | B11: 30 | C11: job | E11: GIẢ ĐỊNH: 1 server chơi 30 ván/tháng (≈ 2 tối/tuần × 4 ván). Cần xác minh ở pilot tháng 1. | F11: Lương tối thiểu vùng I (₫ / giờ) | G11: 25500
A12: → Trần theo giá trị — mức 10% | B12: =IF(B11=0,0,B10*0.1/B11) -> 0.019487963 | C12: $/job | F12: → Chi phí thời gian quản trò / ván ($) | G12: =G10*G11/'1_Cost_Job'!B68 -> 0.19487963
A13: → Trần theo giá trị — mức 25% | B13: =IF(B11=0,0,B10*0.25/B11) -> 0.048719908 | C13: $/job | F13: 0,2 giờ ≈ 12 phút: 2 vòng × (đêm ≥ 30s + thảo luận 120s + bỏ phiếu 60s + trăn trối 30s) + mở màn, tổng kết. Thời gian lấy từ code (discussion.py, voting_view.py, lynch_execution.py, timer.py). Lương: Nghị định 293/2025/NĐ-CP, hiệu lực 01/01/2026.
A14: Lương / tháng của vị trí bị thay ($) | B14: =G12*B11 -> 5.846389 | D14: Neo theo nhân công | E14: Không thuê quản trò cả tháng, chỉ trả phần thời gian 30 ván × 0,2 giờ, tính theo lương tối thiểu (mức thấp nhất hợp pháp).
A15: → Trần theo nhân công — mức 50% | B15: =IF(B11=0,0,B14*0.5/B11) -> 0.097439817 | C15: $/job
A16: → Trần theo nhân công — mức 70% | B16: =IF(B11=0,0,B14*0.7/B11) -> 0.13641574 | C16: $/job
A18: GIÁ BÁN CỦA BẠN | F18: GÓI BÁN
A19: ★ Giá bán đề xuất ($ / job) | B19: =G19/G20 -> 0.133 | C19: $/job | D19: Tham chiếu: Intercom Fin $0,99 · Zendesk $1,50 | E19: Giá / ván = gói $3,99 / 30 ván ≈ $0,133. Nằm dưới trần 70% nhân công. Thấp hơn hẳn Friends & Fables ($19,95/tháng) vì Ma Sói ván ngắn, ít lượt AI. | F19: Gói server ($ / tháng) | G19: 3.99
A20: → Bội số so với Cost/Job | B20: =IF(B5=0,0,B19/B5) -> 3.0613124 | F20: Số ván hoàn thành trong gói | G20: =B11 -> 30
A21: → GROSS MARGIN | B21: =IF(B19=0,0,(B19-B5)/B19) -> 0.67334271 | F21: Phí vượt gói ($ / ván hoàn thành) | G21: =B19 -> 0.133
A22: → Đèn: bội số ≥ 3? | B22: =IF(B20>=B6,"OK — ĐẠT","KHÔNG ĐẠT — quay lại tab 1") -> OK — ĐẠT
A23: → Đèn: Gross Margin | B23: =IF(B21>=0.6,"OK — AN TOÀN (≥60%)",IF(B21>=0.5,"CẢNH BÁO (50–60%)","NGUY HIỂM (<50%)")) -> OK — AN TOÀN (≥60%)
A24: → Đèn: GM có cao bất thường? | B24: =IF(B21>0.85,"NGHI NGỜ — nhiều khả năng bạn quên một khoản chi phí","OK") -> OK
A25: → Giá bán nằm trong vùng neo? | B25: =IF(AND(B19>=B7,B19<=MAX(B13,B16)),"OK — trong vùng giá bán","XEM LẠI — ngoài vùng giá sàn/trần") -> OK — trong vùng giá bán
A27: BREAKEVEN CONTAINMENT — ngưỡng sống còn
A28: Ký hiệu: v = chi phí biến đổi / job thử · q = QA / job thử · e = chi phí 1 ca escalate
A29: v — chi phí biến đổi / job thử | B29: ='1_Cost_Job'!B31+'1_Cost_Job'!B38+'1_Cost_Job'!B43+'1_Cost_Job'!B47 -> 0.032456263
A30: q — QA nội bộ / job thử | B30: ='1_Cost_Job'!B51*('1_Cost_Job'!B52/60)*'1_Cost_Job'!B50 -> 0.0047764616
A31: e — chi phí 1 ca escalate | B31: =IF('1_Cost_Job'!B6="B",('1_Cost_Job'!B53/60)*'1_Cost_Job'!B50,0) -> 0
A32: Gross Margin mục tiêu | B32: 0.6
A33: ★ Containment tối thiểu cần đạt | B33: =IF((B19*(1-B32)+B31)=0,0,(B29+B30+B31)/(B19*(1-B32)+B31)) -> 0.69986324 | D33: Công thức: R ≥ (v+q+e) / (P×(1−GM)+e)
A34: Containment hiện tại (từ tab 1) | B34: ='1_Cost_Job'!B10 -> 0.857
A35: → Kết luận | B35: =IF(B34>=B33,"ĐẠT — mô hình có lãi lành mạnh","CHƯA ĐẠT — phải tăng containment, tăng giá, hoặc đổi biến thể HITL") -> ĐẠT — mô hình có lãi lành mạnh
A37: SENSITIVITY — mô hình gãy ở đâu? | F37: THEO KHỐI LƯỢNG — Railway là chi phí cố định
A38: Containment | B38: Cost/Job | C38: Gross Margin | D38: Đánh giá | F38: Ván thử / tháng | G38: Cost/Job | H38: Gross Margin
A39: 0.5 | B39: =($B$29+$B$30+$B$31*(1-A39))/A39 -> 0.074465449 | C39: =IF($B$19=0,0,1-B39/$B$19) -> 0.44010941 | D39: =IF(C39>=0.6,"An toàn",IF(C39>=0.5,"Cảnh báo","Nguy hiểm")) -> Nguy hiểm | F39: 300 | G39: =($B$29-'1_Cost_Job'!$G$38+'1_Cost_Job'!$G$36/F39+$B$30)/'1_Cost_Job'!$B$10 -> 0.11345709 | H39: =IF($B$19=0,0,1-G39/$B$19) -> 0.14693919
A40: 0.6 | B40: =($B$29+$B$30+$B$31*(1-A40))/A40 -> 0.06205454 | C40: =IF($B$19=0,0,1-B40/$B$19) -> 0.53342451 | D40: =IF(C40>=0.6,"An toàn",IF(C40>=0.5,"Cảnh báo","Nguy hiểm")) -> Cảnh báo | F40: 600 | G40: =($B$29-'1_Cost_Job'!$G$38+'1_Cost_Job'!$G$36/F40+$B$30)/'1_Cost_Job'!$B$10 -> 0.074561716 | H40: =IF($B$19=0,0,1-G40/$B$19) -> 0.43938559
A41: 0.7 | B41: =($B$29+$B$30+$B$31*(1-A41))/A41 -> 0.053189606 | C41: =IF($B$19=0,0,1-B41/$B$19) -> 0.60007815 | D41: =IF(C41>=0.6,"An toàn",IF(C41>=0.5,"Cảnh báo","Nguy hiểm")) -> An toàn | F41: 1500 | G41: =($B$29-'1_Cost_Job'!$G$38+'1_Cost_Job'!$G$36/F41+$B$30)/'1_Cost_Job'!$B$10 -> 0.051224494 | H41: =IF($B$19=0,0,1-G41/$B$19) -> 0.61485343
A42: 0.8 | B42: =($B$29+$B$30+$B$31*(1-A42))/A42 -> 0.046540905 | C42: =IF($B$19=0,0,1-B42/$B$19) -> 0.65006838 | D42: =IF(C42>=0.6,"An toàn",IF(C42>=0.5,"Cảnh báo","Nguy hiểm")) -> An toàn | F42: 3000 | G42: =($B$29-'1_Cost_Job'!$G$38+'1_Cost_Job'!$G$36/F42+$B$30)/'1_Cost_Job'!$B$10 -> 0.043445419 | H42: =IF($B$19=0,0,1-G42/$B$19) -> 0.67334271
A43: 0.9 | B43: =($B$29+$B$30+$B$31*(1-A43))/A43 -> 0.041369694 | C43: =IF($B$19=0,0,1-B43/$B$19) -> 0.68894967 | D43: =IF(C43>=0.6,"An toàn",IF(C43>=0.5,"Cảnh báo","Nguy hiểm")) -> An toàn | F43: 6000 | G43: =($B$29-'1_Cost_Job'!$G$38+'1_Cost_Job'!$G$36/F43+$B$30)/'1_Cost_Job'!$B$10 -> 0.039555882 | H43: =IF($B$19=0,0,1-G43/$B$19) -> 0.70258735
A44: 0.95 | B44: =($B$29+$B$30+$B$31*(1-A44))/A44 -> 0.039192341 | C44: =IF($B$19=0,0,1-B44/$B$19) -> 0.70532074 | D44: =IF(C44>=0.6,"An toàn",IF(C44>=0.5,"Cảnh báo","Nguy hiểm")) -> An toàn | F44: → Số ván thử tối thiểu / tháng để GM ≥ 60% | G44: =IFERROR('1_Cost_Job'!$G$36/($B$19*(1-$B$32)*'1_Cost_Job'!$B$10-($B$29-'1_Cost_Job'!$G$38)-$B$30),0) -> 1330.9959
F45: → Tương đương số server (30 ván) | G45: =G44/30 -> 44.36653
...

Sheet 3_Value_Metric
A1: TAB 3 — VALUE METRIC SCORECARD
A2: Trạm 2. Chấm 0 / 1 / 2 điểm cho mỗi câu, theo THỰC TẾ HÔM NAY.
A4: A. ATTRIBUTION — bạn đo được kết quả là do AI tạo ra không?
A5: 1. Tôi có log đầy đủ mỗi job AI xử lý, gắn được với kết quả cuối cùng | B5: 1 | E5: Engine lưu trạng thái ván (Redis/Postgres) nhưng log sự kiện từng ván (eventLogger) mới đang làm.
A6: 2. Tôi có bộ eval đo được tỷ lệ AI làm đúng, có số liệu | B6: 2 | E6: Eval Gate 2 (04/10/2026): độ chính xác nội dung AI 85,7% (12/14 bước), 724 unit test pass, coverage 94%.
A7: 3. Khách hàng đồng ý với cách tôi định nghĩa 'thành công' của một job | B7: 0 | E7: Chưa hỏi admin server nào về định nghĩa 'ván hoàn thành'.
A8: 4. Tôi phân biệt được kết quả do AI tạo ra với kết quả do yếu tố khác | B8: 1 | E8: Phân biệt được ván dừng do lỗi bot (log lỗi) nhưng chưa tách được ván dừng do người chơi tự bỏ.
A9: 5. Tôi viết được định nghĩa chặt như Intercom: cái gì tính tiền, cái gì không | B9: 2 | E9: Đã viết định nghĩa ở tab 1 B5: tính ván có công bố phe thắng; không tính ván hủy giữa chừng.
A10: → ĐIỂM ATTRIBUTION (tối đa 10) | B10: =SUM(B5:B9) -> 6
A12: B. AUTONOMY — AI tự chạy hay cần người?
A13: 1. AI hoàn thành job từ đầu đến cuối, không cần người bấm nút giữa chừng | B13: 2 | E13: Engine + AI điều hành cả ván; chủ phòng chỉ bấm Bắt đầu.
A14: 2. Job chạy được ngoài giờ hành chính mà không ai trực | B14: 2 | E14: Bot chạy 24/7 trên Railway, không cần người trực.
A15: 3. Khi AI không chắc, nó tự chuyển tiếp đúng chỗ — không cần người phân loại | B15: 1 | E15: LLM quá 3 giây thì tự dùng lời dẫn mẫu. Nhưng MT-01: trợ lý luật bịa vai Thám Tử thay vì từ chối (BUG-QA-013).
A16: 4. Tỷ lệ ca phải có người can thiệp dưới 20% | B16: 1 | E16: Chưa đo tỷ lệ ván cần người can thiệp. Ước tính từ eval: 2/14 bước nội dung AI sai.
A17: 5. Người vận hành chỉ kiểm tra mẫu (QA), không xử lý từng ca | B17: 2 | E17: Người vận hành chỉ soát log mẫu (tab 1: 5% số ván).
A18: → ĐIỂM AUTONOMY (tối đa 10) | B18: =SUM(B13:B17) -> 8
A20: GỢI Ý CỦA MODEL
A21: → Value Metric gợi ý | B21: =IF(AND(B10>=7,B18>=7),"OUTCOME",IF(AND(B10>=7,B18<7),"USAGE",IF(AND(B10<7,B18>=7),"USAGE (an toàn)","SEAT hoặc HYBRID"))) -> USAGE (an toàn)
A22: Ngưỡng 7/10 là quy ước của bài tập, không phải chuẩn ngành — dùng để buộc bạn ra quyết định, không phải để thay bạn quyết định.
A24: BENCHMARK NGƯỢC — 2 sản phẩm thật cùng loại job
A25: Tên sản phẩm | B25: Value Metric | C25: Giá công bố | D25: Link nguồn
A26: Friends & Fables (AI Game Master trên Discord) | B26: Hybrid: gói tháng + giới hạn lượt ở bản Free (1 lượt = 1 tin AI gửi) | C26: Free 25 lượt/ngày · Starter $19,95 · Pro $29,95 · Legend $39,95 /tháng; bạn bè chơi miễn phí | D26: https://fables.gg/pricing (mở 08/10/2026)
A27: AI Dungeon (AI kể chuyện nhập vai) | B27: Seat: gói thành viên theo tháng | C27: Adventurer $9,99 · Champion $14,99 · Legend $29,99 · Mythic $49,99 /tháng | D27: https://play.aidungeon.com/pricing — trang dùng JS, không đọc được trực tiếp; giá lấy từ trang membership của Latitude qua tìm kiếm 08/10/2026, cần mở tay kiểm tra
A29: QUYẾT ĐỊNH CUỐI
A30: Value Metric tôi chọn | B30: Hybrid
A31: Nếu KHÁC gợi ý — lý do thị trường là gì? | B31: Model gợi ý Usage (an toàn) vì Attribution chỉ 6/10. Chọn Hybrid vì thói quen trả tiền của thị trường: bot Discord và AI quản trò (Friends & Fables, AI Dungeon) đều bán gói tháng; Discord Premium Apps cũng bán theo subscription. Tính tiền lẻ từng ván ~3.500 ₫ tạo ma sát thanh toán lớn hơn giá trị. Phần vượt gói vẫn tính theo ván nên chi phí và doanh thu đi cùng chiều.
A32: Decision Note — câu 1: tôi chọn đơn vị nào? | B32: Gói $3,99 / server / tháng gồm 30 ván hoàn thành; vượt gói tính $0,133 / ván hoàn thành. Phí nền mua đúng 30 ván, không phải chỗ ngồi.
A33: Decision Note — câu 2: bằng chứng Attribution / Autonomy? | B33: Attribution 6/10: đếm được ván hoàn thành nhưng chưa đo tỷ lệ thật và chưa hỏi khách. Autonomy 8/10: engine + AI tự chạy cả ván, có lời dẫn mẫu khi LLM chậm; eval Gate 2: 85,7% nội dung AI đúng, các ca luồng chơi MT-03/04/05 PASS 2/2 lần.
A34: Decision Note — câu 3: mô hình này lỗ trong tình huống nào? | B34: Lỗ khi server dùng ít ván nhưng hỏi luật nhiều (mỗi câu ~8.500 token), hoặc khi tổng số ván thấp khiến phí Railway cố định chia cho quá ít ván (xem tab 2, bảng theo khối lượng).

Sheet 4_Channel_Fit
A1: TAB 4 — CHANNEL FIT & AFFORDABILITY TEST
A2: Trạm 4. Chọn ĐÚNG 1 kênh cho 90 ngày đầu — và chứng minh bằng số.
A4: A. NGÂN SÁCH CAC — bạn nuôi nổi kênh nào?
A5: ARPU / tháng ($) | B5: ='2_Pricing'!G19 -> 3.99 | E5: ARPU = giá gói $3,99/tháng. Chưa cộng phí vượt gói (thận trọng).
A6: Gross Margin (từ tab 2_Pricing) | B6: ='2_Pricing'!B21 -> 0.67334271
A7: Phân khúc (SMB / Mid / Enterprise) | B7: SMB | E7: Khách là admin server cộng đồng (cá nhân/nhóm nhỏ) → gần nhất với SMB, payback 12 tháng.
A8: → CAC payback cho phép (tháng) | B8: =IF(B7="SMB",12,IF(B7="Mid",18,24)) -> 12 | C8: tháng | D8: Bessemer, Scaling to $100M (2024)
A9: ★ NGÂN SÁCH CAC / khách | B9: =B5*B6*B8 -> 32.239649 | D9: ARPU × GM × số tháng payback
A10: → ACV (giá trị hợp đồng / năm) | B10: =B5*12 -> 47.88
A12: B. SALES VIABILITY — một AE phải chốt bao nhiêu deal?
A13: Quota / AE / năm ($) | B13: 500000 | D13: Giả định gốc của Tunguz (2016) — thay bằng số thị trường bạn | E13: Giữ giả định gốc Tunguz (2016). Có giảm quota 10 lần thì vẫn > 4 deal/ngày → kết luận không đổi.
A14: Số ngày làm việc / năm | B14: 250 | C14: ngày
A15: → Số deal / AE / năm | B15: =IF(B10=0,0,B13/B10) -> 10442.774
A16: ★ Số deal / AE / NGÀY | B16: =IF(B14=0,0,B15/B14) -> 41.771094 | C16: deal/ngày
A17: → Kết luận Sales-Led | B17: =IF(B16<=1,"KHẢ THI về mặt số học","BẤT KHẢ THI — ACV quá thấp để nuôi sales rep") -> BẤT KHẢ THI — ACV quá thấp để nuôi sales rep
A19: C. ĐỐI CHIẾU CAC THỰC TẾ CỦA MOTION CÓ SALES
A20: Cost per opportunity ($) | B20: 6300 | D20: ICONIQ 2026 theo phân khúc: $6.300 · $8.000 · $11.200 | E20: Mức thấp nhất của ICONIQ 2026 — thuận lợi nhất cho Sales-Led mà vẫn không khả thi.
A21: Win rate | B21: 0.25 | E21: Theo ví dụ trong đề lab (win rate 25%). Nhóm chưa có số liệu bán hàng.
A22: → CAC thực tế ước tính / khách | B22: =IF(B21=0,0,B20/B21) -> 25200
A23: ★ Lệch bao nhiêu lần so với ngân sách CAC? | B23: =IF(B9=0,0,B22/B9) -> 781.64622 | D23: Đây là bằng chứng chọn kênh của bạn
A24: → Kết luận | B24: =IF(B23<=1,"Motion có sales KHẢ THI",IF(B23<=3,"Căng — cần tăng giá hoặc giảm chi phí bán hàng","KHÔNG KHẢ THI — đi PLG hoặc Partner-Led")) -> KHÔNG KHẢ THI — đi PLG hoặc Partner-Led
A26: D. CHẤM ĐIỂM 3 KÊNH (1 = rất kém, 5 = rất tốt)
A27: Tiêu chí | B27: PLG | C27: Sales-Led | D27: Partner-Led
A28: 1. Ngân sách CAC của tôi nuôi nổi kênh này | B28: 4 | C28: 1 | D28: 2 | E28: PLG gần như không tốn CAC; sales cần ~$25.200/khách so với ngân sách ~$30.
A29: 2. Khách hàng mục tiêu thực sự mua theo cách này | B29: 4 | C29: 1 | D29: 2 | E29: Người dùng Discord tự cài bot, tự mua gói ngay trong Discord.
A30: 3. Đội hiện tại có năng lực chạy kênh này ngay | B30: 4 | C30: 1 | D30: 2 | E30: Đội đã có bot chạy trên Discord; chưa có người làm sales, chưa có partner.
A31: 4. Tôi tiếp cận được điểm nhúng / partner trong 30 ngày | B31: 3 | C31: 2 | D31: 1 | E31: Đăng App Directory cần đủ điều kiện xét duyệt của Discord (chưa kiểm tra) → 3.
A32: 5. Kênh này đưa tôi đến ĐÚNG Pain Moment | B32: 5 | C32: 2 | D32: 3 | E32: Pain moment xảy ra ngay trong Discord (xem tab 5).
A33: 6. Tôi đo được hiệu quả trong vòng 90 ngày | B33: 4 | C33: 3 | D33: 2 | E33: Đo được số server cài, số ván, tỷ lệ mua gói qua log bot.
A34: → TỔNG ĐIỂM | B34: =SUM(B28:B33) -> 24 | C34: =SUM(C28:C33) -> 10 | D34: =SUM(D28:D33) -> 12
A35: → Kênh điểm cao nhất | B35: =IF(AND(B34>=C34,B34>=D34),"PLG",IF(C34>=D34,"Sales-Led","Partner-Led")) -> PLG
A37: E. CHỐT KÊNH
A38: ★ Kênh tôi chọn cho 90 ngày đầu | B38: PLG | D38: ĐÚNG 1 kênh. Chọn 2 kênh trở lên bị trừ điểm. | E38: PLG qua Discord App Directory + Discord Premium Apps.
A39: Nếu Partner-Led: TÊN CÔNG TY partner | B39: Không áp dụng — chọn PLG | D39: 'Các nền tảng trong ngành' = chưa có kênh
A40: Đã nói chuyện với họ chưa? (Rồi / Chưa) | B40: Không áp dụng
A41: Bạn mang lại giá trị gì cho partner? | B41: Không áp dụng
A42: Nếu rơi vào vùng không khả thi — lối thoát nào? | B42: Giảm giá để tự phục vụ: gói $3,99 mua thẳng trong Discord, không cần ai tư vấn. Bản miễn phí chỉ dùng lời dẫn mẫu (không gọi LLM) để không tốn chi phí AI; 30 ngày tới mời 5 server dùng thử và đo tỷ lệ ván hoàn thành. | D42: Giảm giá để tự phục vụ / tăng giá + service / Partner-Led

Sheet 5_90Day_Plan
A1: TAB 5 — PAIN MOMENT · 90-DAY PLAN · EVIDENCE PACK
A2: Trạm 5 và Trạm 6.
A4: A. PAIN MOMENT — phải đủ 3 phần
A5: MẤY GIỜ khách đau nhất? | B5: Khoảng 20h–23h tối (GIẢ ĐỊNH — xác minh bằng giờ tạo phòng trong log pilot tháng 1)
A6: Lúc đó họ ĐANG LÀM GÌ? | B6: Nhóm 5–12 người đang trong server muốn mở ván Ma Sói, nhưng phải có 1 người ngồi ngoài làm quản trò, không được chơi, dễ dẫn sai luật
A7: Họ đang DÙNG APP / KÊNH NÀO? | B7: Discord (kênh text + voice của server)
A8: → Điểm nhúng cụ thể của bạn | B8: Slash command /ma-soi của bot trong chính server Discord; cài từ Discord App Directory; mua gói qua Discord Premium Apps | D8: Một bề mặt tích hợp có tên, không phải 'website của chúng tôi'
A10: B. 90-DAY PLAN
B11: THÁNG 1 — Học | C11: THÁNG 2–3 — Đòn bẩy | D11: THÁNG 4+ — Mở rộng
A12: Kênh sử dụng | B12: PLG thủ công: tự mời bot vào server | C12: Discord App Directory | D12: Discord App Directory + server cộng đồng board game
A13: Mục tiêu số khách | B13: 5 server dùng miễn phí | C13: 20 server trả phí (600 ván/tháng) | D13: 100 server trả phí (3.000 ván/tháng)
A14: Việc cụ thể 1 | B14: Bật eventLogger: đo tỷ lệ ván hoàn thành, số vòng/ván, số câu hỏi luật/ván | C14: Đăng App Directory, bật gói $3,99 qua Premium Apps | D14: Thử ngách quán board game / CLB Ma Sói offline với bản giọng đọc (TTS)
A15: Việc cụ thể 2 | B15: Phỏng vấn 5 admin: có trả $3,99/tháng không, định nghĩa 'ván hoàn thành' có đúng không | C15: Bản miễn phí dùng lời dẫn mẫu (không gọi LLM), giới hạn số ván | D15: Chỉ mở rộng khi tỷ lệ ván hoàn thành ≥ ngưỡng breakeven ở tab 2
A16: Việc cụ thể 3 | B16: Lấy hóa đơn OpenAI + Railway thật, thay các ô ước tính ở tab 1 | C16: Sửa BUG-QA-012/013; trợ lý luật chỉ gửi đoạn luật liên quan (RAG) thay vì cả rulebook | D16: Viết Pilot Report thứ 2 cho ngách mới
A17: KPI đo được | B17: ≥ 30 ván hoàn thành có log; 5 phỏng vấn; completion rate đo được | C17: 20 server trả phí; tỷ lệ miễn phí → trả phí; token/ván giảm | D17: 100 server trả phí; GM ≥ 60% theo hóa đơn thật
A18: Người chịu trách nhiệm | B18: Điền (eventLogger) · Nhung (phỏng vấn) · Chinh (chi phí AI) · Sơn (tìm server) | C18: Sơn (App Directory) · Chinh (RAG, sửa bug AI) · Điền (gói trả phí) | D18: Nhung (Pilot Report) · Sơn (ngách offline)
A19: Tháng 1 là giai đoạn HỌC, không phải scale. Kế hoạch 'tháng 1 lấy 200 khách ở 5 ngành' là kế hoạch chưa ai từng thử làm.
A21: C. EVIDENCE PACK — 3 tài sản bán hàng
A22: Tài sản | B22: Đã có? (Rồi/Chưa) | C22: Nội dung 1 câu — hoặc việc cần làm | D22: Người phụ trách · Deadline
A23: 1. Eval Results | B23: Rồi (một phần) | C23: Gate 2: 85,7% nội dung AI đúng (12/14), 724 test pass, hài lòng 4,6/5 (5 người). Thiếu: tỷ lệ ván hoàn thành. | D23: Bổ sung completion rate: Điền · 08/11/2026
A24: 2. Risk Checklist | B24: Chưa | C24: Trả lời bằng văn bản 3 câu: AI có bịa không (có lỗi BUG-QA-013, đang sửa); dữ liệu có bị dùng huấn luyện model không; dừng dịch vụ thì dữ liệu ván ở đâu, xóa thế nào. | D24: Nhung · 22/10/2026
A25: 3. Pilot Report | B25: Chưa | C25: Pilot 5 server trong tháng 1: số ván, tỷ lệ hoàn thành, phản hồi admin, chi phí thật / ván. | D25: Sơn + Nhung · 08/11/2026
A26: Ô nào CHƯA CÓ thì ghi deadline — đừng bỏ trống. Thành thật về khoảng trống được điểm cao hơn bịa nội dung.
A28: D. BÀI TEST NGƯỜI LẠ — nhóm khác đọc One-Pager trong 2 phút
A29: Họ trả lời được: bán gì, cho ai, tính tiền theo đơn vị nào? (Được/Không) | B29: Chưa test
A30: Họ trả lời được: có lãi trên mỗi đơn vị không, số nào chứng minh? (Được/Không) | B30: Chưa test
A31: Họ trả lời được: tiếp cận khách qua đâu, vì sao kênh đó? (Được/Không) | B31: Chưa test
A32: Số câu họ phải hỏi lại (mục tiêu ≤ 3) | B32: Chưa test — nhờ nhóm khác đọc One-Pager trước khi nộp

Sheet 6_Benchmarks
A1: TAB 6 — BENCHMARKS (CHỈ ĐỌC)
A2: Giá chốt ngày 26/08/2026. Dòng có ⏳ là GIÁ KHUYẾN MẠI CÓ HẠN — phải kiểm tra lại.
A3: NGÀY BẠN KIỂM TRA LẠI GIÁ | B3: 08/10/2026 | D3: Bắt buộc điền — Rubric có chấm mục này
A5: Nhóm | B5: Mục | C5: Giá | D5: Đơn vị | E5: Nguồn
A6: LLM | B6: Claude Opus 5 — input / output | C6: 5,00 / 25,00 | D6: $ / 1M token | E6: platform.claude.com/docs/en/about-claude/pricing
A7: LLM | B7: Claude Sonnet 5 — input / output | C7: 2,00 / 10,00 | D7: $ / 1M token | E7: platform.claude.com/docs/en/about-claude/pricing
A8: LLM | B8: Claude Haiku 4.5 — input / output | C8: 1,00 / 5,00 | D8: $ / 1M token | E8: platform.claude.com/docs/en/about-claude/pricing
A9: LLM | B9: Claude — cache write 5' / cache read | C9: 1,25× / 0,10× input | D9: hệ số | E9: platform.claude.com/docs/en/about-claude/pricing
A10: LLM | B10: ⏳ OpenAI GPT-5.6 Sol — input / output | C10: 4,00 / 20,00 | D10: $ / 1M token | E10: developers.openai.com/api/docs/pricing (KM 21/08–21/11/2026; list 5,00/30,00)
A11: LLM | B11: OpenAI GPT-5.6 Luna — input / output | C11: 0,20 / 1,20 | D11: $ / 1M token | E11: developers.openai.com/api/docs/pricing
A12: LLM | B12: OpenAI — cached input / Batch API | C12: 10% input / −50% | D12: hệ số | E12: developers.openai.com/api/docs/pricing
A13: LLM | B13: Gemini 3.1 Pro — input / output (≤200k) | C13: 2,00 / 12,00 | D13: $ / 1M token | E13: ai.google.dev/gemini-api/docs/pricing
A14: LLM | B14: ⏳ Gemini 3.7 Flash — input / output | C14: 0,75 / 3,75 | D14: $ / 1M token | E14: ai.google.dev/gemini-api/docs/pricing (KM đến 31/12/2026; sau đó 1,50/7,50)
A15: STT | B15: Deepgram Nova-3 — pre-recorded | C15: 0,0043 | D15: $ / phút | E15: deepgram.com/pricing
A16: STT | B16: ⏳ Deepgram Nova-3 — streaming | C16: list 0,0077 · KM 0,0048 | D16: $ / phút | E16: deepgram.com/pricing — đang khuyến mại, kiểm tra lại
... A41: Benchmark | B41: ACV sàn cho inside sales | C41: ≈ 3.000 | D41: $ / năm | E41: Tomasz Tunguz (2016) — có kèm giả định để tính lại
A43: Lưu ý: trang marketing của nhà cung cấp có thể hiển thị giá cũ hơn trang docs. Ưu tiên trang docs / pricing chính thức.
A45: GIÁ ĐÃ KIỂM TRA LẠI CHO SẢN PHẨM NÀY (08/10/2026)
A46: LLM | B46: OpenAI gpt-4o-mini — input / cached / output | C46: 0,15 / 0,075 / 0,60 | D46: $ / 1M token | E46: developers.openai.com/api/docs/pricing (Batch 0,075 / 0,30)
A47: Infra | B47: Railway Pro | C47: 20 (gồm 20 usage) | D47: $ / tháng | E47: railway.com/pricing — RAM ~10 $/GB, CPU ~20 $/vCPU
A48: Phí kênh | B48: Discord Premium Apps | C48: 15% ($1M đầu), sau đó 30% | D48: % doanh thu | E48: discord.com/blog/feast-your-moniteyes-on-todays-exciting-developer-updates (06/2024)
A49: Lương | B49: Lương tối thiểu vùng I 2026 | C49: 25.500 / giờ · 5.310.000 / tháng | D49: ₫ | E49: Nghị định 293/2025/NĐ-CP, hiệu lực 01/01/2026
A50: Tỷ giá | B50: Vietcombank bán USD (28/09/2026) | C50: 26.170 | D50: ₫ / USD | E50: webgia.com/ty-gia/vietcombank/28-09-2026.html
A51: Sản phẩm | B51: Friends & Fables | C51: 19,95 / 29,95 / 39,95 | D51: $ / tháng | E51: fables.gg/pricing
A52: Sản phẩm | B52: AI Dungeon | C52: 9,99 / 14,99 / 29,99 / 49,99 | D52: $ / tháng | E52: Chưa mở được trang giá chính (JS) — số từ tìm kiếm, cần kiểm tra tay
